<?xml version="1.0"?>
<robot name="denso" xmlns:xacro="http://www.ros.org/wiki/xacro">

  <!-- Import all Gazebo-customization elements, including Gazebo colors -->
  <xacro:include filename="$(find vs060_gazebo)/urdf/vs060.gazebo" />
  <!-- Import transmission file -->
  <xacro:include filename="$(find vs060_gazebo)/urdf/vs060.transmission.xacro" />
  <!-- Import colors -->
  <xacro:include filename="$(find vs060_gazebo)/urdf/materials.xacro" />
  
  <!-- Used for fixing robot to Gazebo 'base_link' -->
  <link name="world"/>

  <joint name="fixed" type="fixed">
    <parent link="world"/>
    <child link="BASE"/>
  </joint>  
  
  <link name="BASE">
    <visual>
      <origin xyz="0 0 0" rpy="0 -0 0"/>
      <geometry>
        <mesh filename="package://vs060/model/meshes/BASE_mesh.stl"/>
      </geometry>
    </visual>
    <collision>
      <origin xyz="0 0 0" rpy="0 -0 0"/>
      <geometry>
        <mesh filename="package://vs060/model/meshes/BASE_mesh.stl"/>
      </geometry>
    </collision>
    <inertial>
      <mass value="1000" />
      <origin xyz="0 0 0" rpy="0 -0 0"/>
      <inertia ixx="20" ixy="0" ixz="0" iyy="20" iyz="0" izz="20"/>
    </inertial>
  </link>
  <link name="link_1">
    <visual>
      <origin xyz="0 4.04121e-17 0.182" rpy="0 -0 0"/>
      <geometry>
        <mesh filename="package://vs060/model/meshes/J1_mesh.stl"/>
      </geometry>
    </visual>
    <collision>
      <origin xyz="0 4.04121e-17 0.182" rpy="0 -0 0"/>
      <geometry>
        <mesh filename="package://vs060/model/meshes/J1_mesh.stl"/>
      </geometry>
    </collision>
    <inertial>
      <mass value="4.327" />
      <origin xyz="0.013885 -0.005997 0.043991" rpy="0 -0 0"/>
      <inertia ixx="0.025492" ixy="0" ixz="0" iyy="0.032502" iyz="-3.26672e-18" izz="0.01779"/>
    </inertial>
  </link>
  <link name="link_2">
    <visual>
      <origin xyz="0 3.61933e-17 0.163" rpy="0 -0 0"/>
      <geometry>
        <mesh filename="package://vs060/model/meshes/J2_mesh.stl"/>
      </geometry>
    </visual>
    <collision>
      <origin xyz="0 3.61933e-17 0.163" rpy="0 -0 0"/>
      <geometry>
        <mesh filename="package://vs060/model/meshes/J2_mesh.stl"/>
      </geometry>
    </collision>
    <inertial>
      <mass value="9.475" />
      <origin xyz="0.015837 -0.073696 0.010087" rpy="0 -0 0"/>
      <inertia ixx="0.108024" ixy="0" ixz="0" iyy="0.025579" iyz="1.93827e-17" izz="0.112871"/>
    </inertial>
  </link>
  <link name="link_3">
    <visual>
      <origin xyz="0 6.77236e-17 0.305" rpy="0 -0 0"/>
      <geometry>
        <mesh filename="package://vs060/model/meshes/J3_mesh.stl"/>
      </geometry>
    </visual>
    <collision>
      <origin xyz="0 6.77236e-17 0.305" rpy="0 -0 0"/>
      <geometry>
        <mesh filename="package://vs060/model/meshes/J3_mesh.stl"/>
      </geometry>
    </collision>
    <inertial>
      <mass value="4.097" />
      <origin xyz="0.011544 -0.057408 0.006203" rpy="0 -0 0"/>
      <inertia ixx="0.015999" ixy="0" ixz="0" iyy="0.00638" iyz="2.33191e-18" izz="0.016882"/>
    </inertial>
  </link>
  <link name="link_4">
    <visual>
      <origin xyz="-0.01 3.66374e-17 0.165" rpy="0 -0 0"/>
      <geometry>
        <mesh filename="package://vs060/model/meshes/J4_mesh.stl"/>
      </geometry>
    </visual>
    <collision>
      <origin xyz="-0.01 3.66374e-17 0.165" rpy="0 -0 0"/>
      <geometry>
        <mesh filename="package://vs060/model/meshes/J4_mesh.stl"/>
      </geometry>
    </collision>
    <inertial>
      <mass value="1.779" />
      <origin xyz="0.003998 -0.004975 0.052919" rpy="0 -0 0"/>
      <inertia ixx="0.005106" ixy="0" ixz="0" iyy="0.005266" iyz="-5.87308e-19" izz="0.002621"/>
    </inertial>
  </link>
  <link name="link_5">
    <visual>
      <origin xyz="0 2.9976e-17 0.135" rpy="0 -0 0"/>
      <geometry>
        <mesh filename="package://vs060/model/meshes/J5_mesh.stl"/>
      </geometry>
    </visual>
    <collision>
      <origin xyz="0 2.9976e-17 0.135" rpy="0 -0 0"/>
      <geometry>
        <mesh filename="package://vs060/model/meshes/J5_mesh.stl"/>
      </geometry>
    </collision>
    <inertial>
      <mass value="1.219"/>
      <origin xyz="0.011902 -0.004739 0.010398" rpy="0 -0 0"/>
      <inertia ixx="0.111172755531" ixy="0.0" ixz="0.0" iyy="0.111172755531" iyz="0.0" izz="0.21942"/>
    </inertial>
  </link>
  <link name="Flange">
    <visual>
      <origin xyz="0 1.55431e-17 0.07" rpy="0 -0 0"/>
      <geometry>
        <mesh filename="package://vs060/model/meshes/Flange_mesh.stl"/>
      </geometry>
    </visual>
    <collision>
      <origin xyz="0 1.55431e-17 0.07" rpy="0 -0 0"/>
      <geometry>
        <mesh filename="package://vs060/model/meshes/Flange_mesh.stl"/>
      </geometry>
    </collision>
    <inertial>
      <mass value="0.1879" />
      <origin xyz="-0.000401015 0.0770342 0.0962886" rpy="0 -0 0"/>
      <inertia ixx="0.0171364731454" ixy="0.0" ixz="0.0" iyy="0.0171364731454" iyz="0.0" izz="0.033822"/>
    </inertial>
  </link>
  
  <joint name="j1" type="revolute">
    <parent link="BASE"/>
    <child  link="link_1"/>
    <origin xyz="0 4.04121e-17 0.182" rpy="0 -0 0 "/>
    <axis   xyz="0 0 1"/>
    <limit lower="-2.96706" upper="2.96706" effort="19.7336" velocity="3.2" />
  </joint>
  
  <joint name="j2" type="revolute">
    <parent link="link_1"/>
    <child  link="link_2"/>
    <origin xyz="0 3.61933e-17 0.163" rpy="0 -0 0 "/>
    <axis   xyz="0 1 0"/>
    <limit lower="-2.0944" upper="2.0944" effort="40.8447" velocity="3.2" />    
  </joint>

  <joint name="j3" type="revolute">
    <parent link="link_2"/>
    <child  link="link_3"/>
    <origin xyz="0 6.77236e-17 0.305" rpy="0 -0 0 "/>
    <axis   xyz="0 1 0"/>
    <limit lower="-2.18166" upper="2.70526" effort="20.7089" velocity="3.2" />    
  </joint>

  <joint name="j4" type="revolute">
    <parent link="link_3"/>
    <child  link="link_4"/>
    <origin xyz="-0.01 3.66374e-17 0.165" rpy="0 -0 0 "/>
    <axis   xyz="0 0 1"/>
    <limit lower="-3.14" upper="3.14" effort="28.0" velocity="3.2"/>
  </joint>

  <joint name="j5" type="revolute">
    <parent link="link_4"/>
    <child  link="link_5"/>
    <origin xyz="0 2.9976e-17 0.135" rpy="0 -0 0 "/>
    <axis   xyz="0 1 0"/>
    <limit lower="-2.0944" upper="2.0944" effort="28.0" velocity="3.2"/>    
  </joint>

  <joint name="flange" type="revolute">
    <parent link="link_5"/>
    <child  link="Flange"/>
    <origin xyz="0 1.55431e-17 0.07" rpy="0 -0 0 "/>
    <axis   xyz="0 0 1"/>
    <limit lower="-6.2831853" upper="6.2831853" effort="28.0" velocity="3.2"/>    
  </joint>
  
</robot>
